<?xml version="1.0" ?>
<!-- =================================================================================== -->
<!-- |    This document was autogenerated by xacro from desherborator.urdf.xacro       | -->
<!-- |    EDITING THIS FILE BY HAND IS NOT RECOMMENDED                                 | -->
<!-- =================================================================================== -->
<robot name="desherborator" xmlns:xacro="http://ros.org/wiki/xacro">
  <gazebo reference="Chassis">
    <material>Gazebo/DarkGrey</material>
  </gazebo>
  <gazebo reference="RoueG">
    <mu1>1.2</mu1>
    <mu2>1.2</mu2>
    <kp>500000.0</kp>
    <kd>10.0</kd>
    <minDepth>0.001</minDepth>
    <maxVel>0.1</maxVel>
    <material>Gazebo/FlatBlack</material>
  </gazebo>
  <gazebo reference="RoueD">
    <mu1>1.2</mu1>
    <mu2>1.2</mu2>
    <kp>500000.0</kp>
    <kd>10.0</kd>
    <minDepth>0.001</minDepth>
    <maxVel>0.1</maxVel>
    <material>Gazebo/FlatBlack</material>
  </gazebo>
  <gazebo reference="RoueF">
    <mu1>0.1</mu1>
    <mu2>0.1</mu2>
    <kp>1000000.0</kp>
    <kd>100.0</kd>
    <minDepth>0.001</minDepth>
    <maxVel>1.0</maxVel>
    <material>Gazebo/FlatBlack</material>
  </gazebo>
  <gazebo reference="Mat">
    <material>Gazebo/FlatBlack</material>
  </gazebo>
  <gazebo reference="BrasC1">
    <material>Gazebo/FlatBlack</material>
  </gazebo>
  <gazebo reference="BrasC2">
    <material>Gazebo/FlatBlack</material>
  </gazebo>
  <gazebo reference="BrasC3">
    <material>Gazebo/FlatBlack</material>
  </gazebo>
  <gazebo reference="BrasS1">
    <material>Gazebo/FlatBlack</material>
  </gazebo>
  <gazebo reference="BrasS2">
    <material>Gazebo/FlatBlack</material>
  </gazebo>
  <!-- Base Chassis -->
  <link name="base_link"/>
  <!-- Link Chassis -->
  <link name="Chassis">
    <collision>
      <origin rpy="0 0 0" xyz="0 0 0.05"/>
      <geometry>
        <box size="0.4 0.3 0.2"/>
      </geometry>
    </collision>
    <visual>
      <origin rpy="0 0 0" xyz="0 0 0.05"/>
      <geometry>
        <box size="0.4 0.3 0.2"/>
      </geometry>
    </visual>
    <inertial>
      <origin rpy="0 0 0" xyz="0 0 0.05"/>
      <mass value="1"/>
      <inertia ixx="0.01" ixy="0.0" ixz="0.0" iyy="0.01" iyz="0.0" izz="0.01"/>
    </inertial>
  </link>
  <!-- Link Roue -->
  <!-- link Roue Folle -->
  <link name="RoueF">
    <collision>
      <origin rpy="0 0 0" xyz="0 0 0"/>
      <geometry>
        <sphere radius="0.05"/>
      </geometry>
    </collision>
    <visual>
      <origin rpy="0 0 0" xyz="0 0 0"/>
      <geometry>
        <sphere radius="0.05"/>
      </geometry>
    </visual>
    <inertial>
      <origin rpy="0 0 0" xyz="0 0 0"/>
      <mass value="0.01"/>
      <inertia ixx="0.01" ixy="0.0" ixz="0.0" iyy="0.01" iyz="0.0" izz="0.01"/>
    </inertial>
  </link>
  <!-- link Roue Gauche -->
  <link name="RoueG">
    <collision>
      <origin rpy="0 1.5707 1.5707" xyz="0 0 0"/>
      <geometry>
        <cylinder length="0.1" radius="0.15"/>
      </geometry>
    </collision>
    <visual>
      <origin rpy="0 1.5707 1.5707" xyz="0 0 0"/>
      <geometry>
        <cylinder length="0.1" radius="0.15"/>
      </geometry>
    </visual>
    <inertial>
      <origin rpy="0 0 0" xyz="0 0 0"/>
      <mass value="0.01"/>
      <inertia ixx="0.01" ixy="0.0" ixz="0.0" iyy="0.01" iyz="0.0" izz="0.01"/>
    </inertial>
  </link>
  <!-- link Roue Droite -->
  <link name="RoueD">
    <collision>
      <origin rpy="0 1.5707 1.5707" xyz="0 0 0"/>
      <geometry>
        <cylinder length="0.1" radius="0.15"/>
      </geometry>
    </collision>
    <visual>
      <origin rpy="0 1.5707 1.5707" xyz="0 0 0"/>
      <geometry>
        <cylinder length="0.1" radius="0.15"/>
      </geometry>
    </visual>
    <inertial>
      <origin rpy="0 0 0" xyz="0 0 0"/>
      <mass value="0.01"/>
      <inertia ixx="0.01" ixy="0.0" ixz="0.0" iyy="0.01" iyz="0.0" izz="0.01"/>
    </inertial>
  </link>
  <!-- link Mat -->
  <link name="Mat">
    <collision>
      <origin rpy="0 0 0" xyz="0 0 0"/>
      <geometry>
        <cylinder length="0.2" radius="0.01"/>
      </geometry>
    </collision>
    <visual>
      <origin rpy="0 0 0" xyz="0 0 0"/>
      <geometry>
        <cylinder length="0.2" radius="0.01"/>
      </geometry>
    </visual>
    <inertial>
      <origin rpy="0 0 0" xyz="0 0 0"/>
      <mass value="0.01"/>
      <inertia ixx="0.01" ixy="0.0" ixz="0.0" iyy="0.01" iyz="0.0" izz="0.01"/>
    </inertial>
  </link>
  <!-- link Bras -->
  <!-- link Bras Cylindre 1 -->
  <link name="BrasC1">
    <collision>
      <origin rpy="0 0 0" xyz="0 0 0"/>
      <geometry>
        <cylinder length="0.25" radius="0.01"/>
      </geometry>
    </collision>
    <visual>
      <origin rpy="0 0 0" xyz="0 0 0"/>
      <geometry>
        <cylinder length="0.25" radius="0.01"/>
      </geometry>
    </visual>
    <inertial>
      <origin rpy="0 0 0" xyz="0 0 0"/>
      <mass value="0.01"/>
      <inertia ixx="0.01" ixy="0.0" ixz="0.0" iyy="0.01" iyz="0.0" izz="0.01"/>
    </inertial>
  </link>
  <!-- link Dummy Bras Cylindre 1 -->
  <link name="BrasC1dummy"/>
  <!-- link Bras Cylindre 2 -->
  <link name="BrasC2">
    <collision>
      <origin rpy="0 1.5707 1.5707" xyz="0 0 0"/>
      <geometry>
        <cylinder length="0.3" radius="0.01"/>
      </geometry>
    </collision>
    <visual>
      <origin rpy="0 0 0" xyz="0 0 0"/>
      <geometry>
        <cylinder length="0.3" radius="0.01"/>
      </geometry>
    </visual>
    <inertial>
      <origin rpy="0 1.5707 1.5707" xyz="0 0 0"/>
      <mass value="0.01"/>
      <inertia ixx="0.01" ixy="0.0" ixz="0.0" iyy="0.01" iyz="0.0" izz="0.01"/>
    </inertial>
  </link>
  <!-- link Bras Cylindre 3 -->
  <link name="BrasC3">
    <collision>
      <origin rpy="0 3.14 0" xyz="0 0 0"/>
      <geometry>
        <cylinder length="0.1" radius="0.01"/>
      </geometry>
    </collision>
    <visual>
      <origin rpy="0 3.14 0" xyz="0 0 0"/>
      <geometry>
        <cylinder length="0.1" radius="0.01"/>
      </geometry>
    </visual>
    <inertial>
      <origin rpy="0 0 0" xyz="0 0 0"/>
      <mass value="0.01"/>
      <inertia ixx="0.01" ixy="0.0" ixz="0.0" iyy="0.01" iyz="0.0" izz="0.01"/>
    </inertial>
  </link>
  <!-- link Bras Sphere 1 -->
  <link name="BrasS1">
    <collision>
      <origin rpy="0 0 0" xyz="0 0 0"/>
      <geometry>
        <sphere radius="0.02"/>
      </geometry>
    </collision>
    <visual>
      <origin rpy="0 0 0" xyz="0 0 0"/>
      <geometry>
        <sphere radius="0.02"/>
      </geometry>
    </visual>
    <inertial>
      <origin rpy="0 0 0" xyz="0 0 0"/>
      <mass value="0.01"/>
      <inertia ixx="0.01" ixy="0.0" ixz="0.0" iyy="0.01" iyz="0.0" izz="0.01"/>
    </inertial>
  </link>
  <!-- link Bras Sphere 2 -->
  <link name="BrasS2">
    <collision>
      <origin rpy="0 0 0" xyz="0 0 0"/>
      <geometry>
        <sphere radius="0.02"/>
      </geometry>
    </collision>
    <visual>
      <origin rpy="0 0 0" xyz="0 0 0"/>
      <geometry>
        <sphere radius="0.02"/>
      </geometry>
    </visual>
    <inertial>
      <origin rpy="0 0 0" xyz="0 0 0"/>
      <mass value="0.01"/>
      <inertia ixx="0.01" ixy="0.0" ixz="0.0" iyy="0.01" iyz="0.0" izz="0.01"/>
    </inertial>
  </link>
  <joint name="base_joint" type="fixed">
    <parent link="base_link"/>
    <child link="Chassis"/>
    <origin rpy="0 0 0" xyz="0 0 0.05"/>
  </joint>
  <joint name="mat_attached" type="fixed">
    <parent link="Chassis"/>
    <child link="Mat"/>
    <origin rpy="0 0 0" xyz="-0.3 0 0.2"/>
  </joint>
  <joint name="joint_1" type="continuous">
    <parent link="Chassis"/>
    <child link="RoueD"/>
    <origin rpy="0 0 0" xyz="-0.2 -0.15 0.1"/>
    <axis xyz="0 1 0"/>
  </joint>
  <joint name="joint_2" type="continuous">
    <parent link="Chassis"/>
    <child link="RoueG"/>
    <origin rpy="0 0 0" xyz="-0.2 0.15 0.1"/>
    <axis xyz="0 1 0"/>
  </joint>
  <joint name="joint_3" type="fixed">
    <parent link="Chassis"/>
    <child link="RoueF"/>
    <origin rpy="0 0 0" xyz="-0.3 0 0"/>
  </joint>
  <joint name="joint_4" type="continuous">
    <parent link="Chassis"/>
    <child link="BrasC1dummy"/>
    <origin rpy="0 0 0" xyz="0.01 -0.15 0"/>
    <axis xyz="0 0 1"/>
  </joint>
  <joint name="joint_5" type="prismatic">
    <parent link="BrasC1dummy"/>
    <child link="BrasC1"/>
    <origin rpy="0 0 0" xyz="0 0 0.01"/>
    <axis xyz="0 0 1"/>
    <limit effort="10" lower="0" upper="0.10" velocity="1"/>
  </joint>
  <joint name="joint_6" type="fixed">
    <parent link="BrasC1"/>
    <child link="BrasS1"/>
    <origin rpy="0 0 0" xyz="0 0 0.10"/>
  </joint>
  <joint name="joint_7" type="fixed">
    <parent link="BrasS1"/>
    <child link="BrasC2"/>
    <origin rpy="0  0  0" xyz="0 0 0"/>
  </joint>
  <joint name="joint_8" type="fixed">
    <parent link="BrasC2"/>
    <child link="BrasS2"/>
    <origin rpy="0 0 0" xyz="0 0.3 0"/>
  </joint>
  <joint name="joint_9" type="fixed">
    <parent link="BrasS2"/>
    <child link="BrasC3"/>
    <origin rpy="0 0 0" xyz="0 0 0"/>
  </joint>
  <link name="LIDAR">
    <visual>
      <origin rpy="0 0 0" xyz="0 0 0"/>
      <geometry>
        <cylinder length="0.04" radius="0.03"/>
      </geometry>
    </visual>
    <inertial>
      <mass value="0.1"/>
      <inertia ixx="0.01" ixy="0.0" ixz="0.0" iyy="0.01" iyz="0.0" izz="0.01"/>
    </inertial>
  </link>
  <joint name="lidar_joint" type="fixed">
    <parent link="Chassis"/>
    <child link="LIDAR"/>
    <origin rpy="0 0 0" xyz="0.15 0 0.23"/>
  </joint>
  <gazebo reference="LIDAR">
    <material>Gazebo/Orange</material>
    <sensor name="lidar_sensor" type="ray">
      <pose>0 0 0 0 0 0</pose>
      <visualize>true</visualize>
      <update_rate>5</update_rate>
      <ray>
        <scan>
          <horizontal>
            <samples>720</samples>
            <resolution>1</resolution>
            <min_angle>0.0</min_angle>
            <max_angle>6.28319</max_angle>
          </horizontal>
        </scan>
        <range>
          <min>0.120</min>
          <max>12</max>
          <resolution>0.015</resolution>
        </range>
        <noise>
          <type>gaussian</type>
          <mean>0.0</mean>
          <stddev>0.01</stddev>
        </noise>
      </ray>
      <plugin filename="libgazebo_ros_laser.so" name="gazebo_ros_lds_lfcd_controller">
        <topicName>scan</topicName>
        <!-- ENTER FRAME NAME -->
        <frameName>LIDAR</frameName>
      </plugin>
    </sensor>
  </gazebo>
  <joint name="camera_joint" type="fixed">
    <parent link="Chassis"/>
    <axis xyz="0 0 0"/>
    <origin rpy="0 0 0" xyz="0.3 0 0.1"/>
    <child link="Camera"/>
  </joint>
  <!-- Camera -->
  <link name="Camera">
    <collision>
      <origin rpy="0 0 0" xyz="0 0 0"/>
      <geometry>
        <box size="0.1 0.1 0.1"/>
      </geometry>
    </collision>
    <visual>
      <origin rpy="0 0 0" xyz="0 0 0"/>
      <geometry>
        <box size="0.1 0.1 0.1"/>
      </geometry>
      <material name="red"/>
    </visual>
    <inertial>
      <mass value="1e-5"/>
      <origin rpy="0 0 0" xyz="0 0 0"/>
      <inertia ixx="1e-6" ixy="0" ixz="0" iyy="1e-6" iyz="0" izz="1e-6"/>
    </inertial>
  </link>
  <gazebo reference="Camera">
    <material>Gazebo/Green</material>
    <sensor name="main_camera" type="camera">
      <update_rate>30.0</update_rate>
      <camera name="head">
        <horizontal_fov>1.3962634</horizontal_fov>
        <image>
          <width>1280</width>
          <height>720</height>
          <format>R8G8B8</format>
        </image>
        <clip>
          <near>0.02</near>
          <far>300</far>
        </clip>
        <noise>
          <type>gaussian</type>
          <mean>0.0</mean>
          <stddev>0.007</stddev>
        </noise>
      </camera>
      <plugin filename="libgazebo_ros_camera.so" name="camera_controller">
        <topicName>camera</topicName>
        <frameName>Camera</frameName>
        <alwaysOn>true</alwaysOn>
        <updateRate>0.0</updateRate>
        <cameraName>main_camera</cameraName>
        <imageTopicName>image_raw</imageTopicName>
        <cameraInfoTopicName>camera_info</cameraInfoTopicName>
        <frameName>camera</frameName>
        <hackBaseline>0.07</hackBaseline>
        <distortionK1>0.0</distortionK1>
        <distortionK2>0.0</distortionK2>
        <distortionK3>0.0</distortionK3>
        <distortionT1>0.0</distortionT1>
        <distortionT2>0.0</distortionT2>
      </plugin>
    </sensor>
  </gazebo>
  <link name="LASER">
    <visual>
      <origin rpy="0 0 0" xyz="0 0 0"/>
      <geometry>
        <cylinder length="0.15" radius="0.025"/>
      </geometry>
    </visual>
    <inertial>
      <mass value="0.1"/>
      <inertia ixx="0.01" ixy="0.0" ixz="0.0" iyy="0.01" iyz="0.0" izz="0.01"/>
    </inertial>
  </link>
  <joint name="laser_joint" type="fixed">
    <parent link="Chassis"/>
    <child link="LASER"/>
    <origin rpy="0 0 0" xyz="0.15 0 0.23"/>
  </joint>
  <gazebo reference="LASER">
    <material>Gazebo/Blue</material>
    <sensor name="laser_sensor" type="ray">
      <pose>0 0 0 0 0 0</pose>
      <visualize>true</visualize>
      <update_rate>5</update_rate>
      <ray>
        <scan>
          <horizontal>
            <samples>720</samples>
            <resolution>1</resolution>
            <min_angle>0.0</min_angle>
            <max_angle>0.1</max_angle>
          </horizontal>
        </scan>
        <range>
          <min>0.120</min>
          <max>12</max>
          <resolution>0.015</resolution>
        </range>
        <noise>
          <type>gaussian</type>
          <mean>0.0</mean>
          <stddev>0.01</stddev>
        </noise>
      </ray>
      <plugin filename="libgazebo_ros_laser.so" name="gazebo_ros_lds_lfcd_controller">
        <topicName>scan_laser</topicName>
        <!-- ENTER FRAME NAME -->
        <frameName>laser</frameName>
      </plugin>
    </sensor>
  </gazebo>
  <gazebo>
    <plugin filename="libgazebo_ros_diff_drive.so" name="wheels_controller">
      <commandTopic>cmd_vel</commandTopic>
      <odometryTopic>odom</odometryTopic>
      <odometryFrame>odom</odometryFrame>
      <odometrySource>world</odometrySource>
      <publishOdomTF>true</publishOdomTF>
      <!-- ENTER BASE LINK NAME -->
      <robotBaseFrame>Chassis</robotBaseFrame>
      <publishWheelTF>true</publishWheelTF>
      <publishTf>true</publishTf>
      <publishWheelJointState>true</publishWheelJointState>
      <legacyMode>true</legacyMode>
      <updateRate>30</updateRate>
      <!-- ENTER LEFT JOINT NAME -->
      <leftJoint>joint_2</leftJoint>
      <!-- ENTER RIGHT JOINT NAME -->
      <rightJoint>joint_1</rightJoint>
      <wheelSeparation>0.31</wheelSeparation>
      <wheelDiameter>0.1</wheelDiameter>
      <wheelAcceleration>0.1</wheelAcceleration>
      <wheelTorque>10</wheelTorque>
      <rosDebugLevel>na</rosDebugLevel>
    </plugin>
  </gazebo>
</robot>

